time="2025-11-01T17:12:50+01:00" level=warning msg="/home/gabriele/thesis-project/Agents-for-Vulnerable-Dockers-and-related-Benchmarks/dockers/CVE-2021-26120/custom_no_tool/docker-compose.yml: the attribute `version` is obsolete, it will be ignored, please remove it to avoid potential confusion"
#1 [internal] load local bake definitions
#1 reading from stdin 1.35kB done
#1 DONE 0.0s

#2 [vulnerable_app internal] load build definition from Dockerfile
#2 transferring dockerfile: 250B done
#2 DONE 0.0s

#3 [db internal] load build definition from Dockerfile
#3 transferring dockerfile: 94B done
#3 DONE 0.0s

#4 [vulnerable_app internal] load metadata for docker.io/library/python:3.9-slim
#4 ...

#5 [db internal] load metadata for docker.io/library/mysql:5.7
#5 DONE 0.5s

#6 [db internal] load .dockerignore
#6 transferring context: 2B done
#6 DONE 0.0s

#7 [db internal] load build context
#7 transferring context: 229B done
#7 DONE 0.0s

#8 [db 1/2] FROM docker.io/library/mysql:5.7@sha256:4bc6bc963e6d8443453676cae56536f4b8156d78bae03c0145cbe47c2aad73bb
#8 resolve docker.io/library/mysql:5.7@sha256:4bc6bc963e6d8443453676cae56536f4b8156d78bae03c0145cbe47c2aad73bb 0.0s done
#8 CACHED

#9 [db 2/2] COPY init.sql /docker-entrypoint-initdb.d/
#9 DONE 0.0s

#10 [db] exporting to image
#10 exporting layers 0.1s done
#10 exporting manifest sha256:f79abbe0581301f55cb56ff72f2cf6a6aa88c307d1347c50254bc95e7198859c 0.0s done
#10 exporting config sha256:b11899ede50e9361f8cd3c465f9ef089bf66df89ce7446d8ea882f71ca33e47e 0.0s done
#10 exporting attestation manifest sha256:5c85036545f8c3d1230e09a81139bb1db8801e87117513d66b77518ffa3045c9 0.0s done
#10 exporting manifest list sha256:6edaf9d00adbdb6f1a9d180f73b5e5766da709806ea3e92f2abfad4558e78697 0.0s done
#10 naming to docker.io/library/vulnerable_mysql:latest done
#10 unpacking to docker.io/library/vulnerable_mysql:latest 0.0s done
#10 DONE 0.2s

#4 [vulnerable_app internal] load metadata for docker.io/library/python:3.9-slim
#4 ...

#11 [db] resolving provenance for metadata file
#11 DONE 0.0s

#4 [vulnerable_app internal] load metadata for docker.io/library/python:3.9-slim
#4 DONE 1.1s

#12 [vulnerable_app internal] load .dockerignore
#12 transferring context: 2B done
#12 DONE 0.0s

#13 [vulnerable_app internal] load build context
#13 transferring context: 1.27kB done
#13 DONE 0.0s

#14 [vulnerable_app 1/4] FROM docker.io/library/python:3.9-slim@sha256:2d97f6910b16bd338d3060f261f53f144965f755599aab1acda1e13cf1731b1b
#14 resolve docker.io/library/python:3.9-slim@sha256:2d97f6910b16bd338d3060f261f53f144965f755599aab1acda1e13cf1731b1b 0.0s done
#14 DONE 0.0s

#15 [vulnerable_app 2/4] RUN pip install flask docker
#15 CACHED

#16 [vulnerable_app 3/4] WORKDIR /app
#16 CACHED

#17 [vulnerable_app 4/4] COPY app.py /app/app.py
#17 DONE 0.0s

#18 [vulnerable_app] exporting to image
#18 exporting layers 0.1s done
#18 exporting manifest sha256:93b5c63cfa1ef26f39aef6d3787edbf26ab7da9502a70b7424ef2d7847156f40 0.0s done
#18 exporting config sha256:943a7ba9c7c29e4038f54bc2293884af4f4612edc732129d2aec14b965c8a0e2 0.0s done
#18 exporting attestation manifest sha256:ee61be1dd8a18ad342890aff81e2523bd84d797966c60c81b18ae3783fcd3b8f 0.0s done
#18 exporting manifest list sha256:617f37ed0e05ab55de1a2fdd5ca27e23fc5513d83673e3cdc0fbe2e004ce829a 0.0s done
#18 naming to docker.io/library/vulnerable_app:latest done
#18 unpacking to docker.io/library/vulnerable_app:latest 0.0s done
#18 DONE 0.2s

#19 [vulnerable_app] resolving provenance for metadata file
#19 DONE 0.0s
 vulnerable_mysql:latest  Built
 vulnerable_app:latest  Built
 Network custom_no_tool_default  Creating
 Network custom_no_tool_default  Created
 Container vulnerable_mysql  Creating
 Container docker_dind  Creating
 Container docker_dind  Created
 Container vulnerable_app  Creating
 Container vulnerable_mysql  Created
 Container vulnerable_app  Created
 Container vulnerable_mysql  Starting
 Container docker_dind  Starting
 Container docker_dind  Started
 Container vulnerable_app  Starting
 Container vulnerable_mysql  Started
 Container vulnerable_app  Started


sudo docker logs b1223b361a83bf564bda827263b3db3d823ff590ecacc3643b2aae7332259982 --details
STDOUT: 
STDERR:  time="2025-11-01T16:12:53.150642470Z" level=info msg="Starting up"
 time="2025-11-01T16:12:53.153005924Z" level=warning msg="could not change group /var/run/docker.sock to docker: group docker not found"
 time="2025-11-01T16:12:53.153293325Z" level=warning msg="Binding to IP address without --tlsverify is insecure and gives root access on this machine to everyone who has access to your network." host="tcp://0.0.0.0:2375"
 time="2025-11-01T16:12:53.153332752Z" level=warning msg="Binding to an IP address, even on localhost, can also give access to scripts run in a browser. Be safe out there!" host="tcp://0.0.0.0:2375"
 time="2025-11-01T16:12:54.153482641Z" level=warning msg="Binding to an IP address without --tlsverify is deprecated. Startup is intentionally being slowed down to show this message" host="tcp://0.0.0.0:2375"
 time="2025-11-01T16:12:54.153532676Z" level=warning msg="Please consider generating tls certificates with client validation to prevent exposing unauthenticated root access to your network" host="tcp://0.0.0.0:2375"
 time="2025-11-01T16:12:54.153577808Z" level=warning msg="You can override this by explicitly specifying '--tls=false' or '--tlsverify=false'" host="tcp://0.0.0.0:2375"
 time="2025-11-01T16:12:54.153588316Z" level=warning msg="Support for listening on TCP without authentication or explicit intent to run without authentication will be removed in the next release" host="tcp://0.0.0.0:2375"
 time="2025-11-01T16:13:09.144218246Z" level=info msg="libcontainerd: started new containerd process" pid=28
 time="2025-11-01T16:13:09.144294673Z" level=info msg="parsed scheme: \"unix\"" module=grpc
 time="2025-11-01T16:13:09.144305377Z" level=info msg="scheme \"unix\" not registered, fallback to default scheme" module=grpc
 time="2025-11-01T16:13:09.144330485Z" level=info msg="ccResolverWrapper: sending update to cc: {[{unix:///var/run/docker/containerd/containerd.sock  <nil> 0 <nil>}] <nil> <nil>}" module=grpc
 time="2025-11-01T16:13:09.144339889Z" level=info msg="ClientConn switching balancer to \"pick_first\"" module=grpc
 time="2025-11-01T16:13:09.155750946Z" level=info msg="starting containerd" revision=269548fa27e0089a8b8278fc4fc781d7f65a939b version=v1.4.3
 time="2025-11-01T16:13:09.172068705Z" level=info msg="loading plugin \"io.containerd.content.v1.content\"..." type=io.containerd.content.v1
 time="2025-11-01T16:13:09.172626098Z" level=info msg="loading plugin \"io.containerd.snapshotter.v1.aufs\"..." type=io.containerd.snapshotter.v1
 time="2025-11-01T16:13:09.177622931Z" level=info msg="skip loading plugin \"io.containerd.snapshotter.v1.aufs\"..." error="aufs is not supported (modprobe aufs failed: exit status 1 \"ip: can't find device 'aufs'\\nmodprobe: can't change directory to '/lib/modules': No such file or directory\\n\"): skip plugin" type=io.containerd.snapshotter.v1
 time="2025-11-01T16:13:09.177666246Z" level=info msg="loading plugin \"io.containerd.snapshotter.v1.btrfs\"..." type=io.containerd.snapshotter.v1
 time="2025-11-01T16:13:09.178162518Z" level=info msg="skip loading plugin \"io.containerd.snapshotter.v1.btrfs\"..." error="path /var/lib/docker/containerd/daemon/io.containerd.snapshotter.v1.btrfs (ext4) must be a btrfs filesystem to be used with the btrfs snapshotter: skip plugin" type=io.containerd.snapshotter.v1
 time="2025-11-01T16:13:09.178193128Z" level=info msg="loading plugin \"io.containerd.snapshotter.v1.devmapper\"..." type=io.containerd.snapshotter.v1
 time="2025-11-01T16:13:09.178214636Z" level=warning msg="failed to load plugin io.containerd.snapshotter.v1.devmapper" error="devmapper not configured"
 time="2025-11-01T16:13:09.178224239Z" level=info msg="loading plugin \"io.containerd.snapshotter.v1.native\"..." type=io.containerd.snapshotter.v1
 time="2025-11-01T16:13:09.178542950Z" level=info msg="loading plugin \"io.containerd.snapshotter.v1.overlayfs\"..." type=io.containerd.snapshotter.v1
 time="2025-11-01T16:13:09.178919780Z" level=info msg="loading plugin \"io.containerd.snapshotter.v1.zfs\"..." type=io.containerd.snapshotter.v1
 time="2025-11-01T16:13:09.179038522Z" level=info msg="skip loading plugin \"io.containerd.snapshotter.v1.zfs\"..." error="path /var/lib/docker/containerd/daemon/io.containerd.snapshotter.v1.zfs must be a zfs filesystem to be used with the zfs snapshotter: skip plugin" type=io.containerd.snapshotter.v1
 time="2025-11-01T16:13:09.179066031Z" level=info msg="loading plugin \"io.containerd.metadata.v1.bolt\"..." type=io.containerd.metadata.v1
 time="2025-11-01T16:13:09.179224586Z" level=warning msg="could not use snapshotter devmapper in metadata plugin" error="devmapper not configured"
 time="2025-11-01T16:13:09.179248194Z" level=info msg="metadata content store policy set" policy=shared
 time="2025-11-01T16:13:09.186287235Z" level=info msg="loading plugin \"io.containerd.differ.v1.walking\"..." type=io.containerd.differ.v1
 time="2025-11-01T16:13:09.186328049Z" level=info msg="loading plugin \"io.containerd.gc.v1.scheduler\"..." type=io.containerd.gc.v1
 time="2025-11-01T16:13:09.186370664Z" level=info msg="loading plugin \"io.containerd.service.v1.introspection-service\"..." type=io.containerd.service.v1
 time="2025-11-01T16:13:09.186422782Z" level=info msg="loading plugin \"io.containerd.service.v1.containers-service\"..." type=io.containerd.service.v1
 time="2025-11-01T16:13:09.186457294Z" level=info msg="loading plugin \"io.containerd.service.v1.content-service\"..." type=io.containerd.service.v1
 time="2025-11-01T16:13:09.186473200Z" level=info msg="loading plugin \"io.containerd.service.v1.diff-service\"..." type=io.containerd.service.v1
 time="2025-11-01T16:13:09.186488005Z" level=info msg="loading plugin \"io.containerd.service.v1.images-service\"..." type=io.containerd.service.v1
 time="2025-11-01T16:13:09.186500409Z" level=info msg="loading plugin \"io.containerd.service.v1.leases-service\"..." type=io.containerd.service.v1
 time="2025-11-01T16:13:09.186515915Z" level=info msg="loading plugin \"io.containerd.service.v1.namespaces-service\"..." type=io.containerd.service.v1
 time="2025-11-01T16:13:09.186545525Z" level=info msg="loading plugin \"io.containerd.service.v1.snapshots-service\"..." type=io.containerd.service.v1
 time="2025-11-01T16:13:09.186556429Z" level=info msg="loading plugin \"io.containerd.runtime.v1.linux\"..." type=io.containerd.runtime.v1
 time="2025-11-01T16:13:09.186983077Z" level=info msg="loading plugin \"io.containerd.runtime.v2.task\"..." type=io.containerd.runtime.v2
 time="2025-11-01T16:13:09.187331898Z" level=info msg="loading plugin \"io.containerd.monitor.v1.cgroups\"..." type=io.containerd.monitor.v1
 time="2025-11-01T16:13:09.187546372Z" level=info msg="loading plugin \"io.containerd.service.v1.tasks-service\"..." type=io.containerd.service.v1
 time="2025-11-01T16:13:09.187579583Z" level=info msg="loading plugin \"io.containerd.internal.v1.restart\"..." type=io.containerd.internal.v1
 time="2025-11-01T16:13:09.187626500Z" level=info msg="loading plugin \"io.containerd.grpc.v1.containers\"..." type=io.containerd.grpc.v1
 time="2025-11-01T16:13:09.187653909Z" level=info msg="loading plugin \"io.containerd.grpc.v1.content\"..." type=io.containerd.grpc.v1
 time="2025-11-01T16:13:09.187669014Z" level=info msg="loading plugin \"io.containerd.grpc.v1.diff\"..." type=io.containerd.grpc.v1
 time="2025-11-01T16:13:09.187676517Z" level=info msg="loading plugin \"io.containerd.grpc.v1.events\"..." type=io.containerd.grpc.v1
 time="2025-11-01T16:13:09.187683720Z" level=info msg="loading plugin \"io.containerd.grpc.v1.healthcheck\"..." type=io.containerd.grpc.v1
 time="2025-11-01T16:13:09.187692323Z" level=info msg="loading plugin \"io.containerd.grpc.v1.images\"..." type=io.containerd.grpc.v1
 time="2025-11-01T16:13:09.187699525Z" level=info msg="loading plugin \"io.containerd.grpc.v1.leases\"..." type=io.containerd.grpc.v1
 time="2025-11-01T16:13:09.187711929Z" level=info msg="loading plugin \"io.containerd.grpc.v1.namespaces\"..." type=io.containerd.grpc.v1
 time="2025-11-01T16:13:09.187726334Z" level=info msg="loading plugin \"io.containerd.internal.v1.opt\"..." type=io.containerd.internal.v1
 time="2025-11-01T16:13:09.188372058Z" level=info msg="loading plugin \"io.containerd.grpc.v1.snapshots\"..." type=io.containerd.grpc.v1
 time="2025-11-01T16:13:09.188404770Z" level=info msg="loading plugin \"io.containerd.grpc.v1.tasks\"..." type=io.containerd.grpc.v1
 time="2025-11-01T16:13:09.188415873Z" level=info msg="loading plugin \"io.containerd.grpc.v1.version\"..." type=io.containerd.grpc.v1
 time="2025-11-01T16:13:09.188422976Z" level=info msg="loading plugin \"io.containerd.grpc.v1.introspection\"..." type=io.containerd.grpc.v1
 time="2025-11-01T16:13:09.188621445Z" level=info msg=serving... address=/var/run/docker/containerd/containerd-debug.sock
 time="2025-11-01T16:13:09.188721579Z" level=info msg=serving... address=/var/run/docker/containerd/containerd.sock.ttrpc
 time="2025-11-01T16:13:09.188814212Z" level=info msg=serving... address=/var/run/docker/containerd/containerd.sock
 time="2025-11-01T16:13:09.188861528Z" level=info msg="containerd successfully booted in 0.034460s"
 time="2025-11-01T16:13:09.198851592Z" level=info msg="parsed scheme: \"unix\"" module=grpc
 time="2025-11-01T16:13:09.198882803Z" level=info msg="scheme \"unix\" not registered, fallback to default scheme" module=grpc
 time="2025-11-01T16:13:09.198898909Z" level=info msg="ccResolverWrapper: sending update to cc: {[{unix:///var/run/docker/containerd/containerd.sock  <nil> 0 <nil>}] <nil> <nil>}" module=grpc
 time="2025-11-01T16:13:09.198905211Z" level=info msg="ClientConn switching balancer to \"pick_first\"" module=grpc
 time="2025-11-01T16:13:09.200177952Z" level=info msg="parsed scheme: \"unix\"" module=grpc
 time="2025-11-01T16:13:09.200193758Z" level=info msg="scheme \"unix\" not registered, fallback to default scheme" module=grpc
 time="2025-11-01T16:13:09.200205362Z" level=info msg="ccResolverWrapper: sending update to cc: {[{unix:///var/run/docker/containerd/containerd.sock  <nil> 0 <nil>}] <nil> <nil>}" module=grpc
 time="2025-11-01T16:13:09.200211064Z" level=info msg="ClientConn switching balancer to \"pick_first\"" module=grpc
 time="2025-11-01T16:13:09.230703738Z" level=info msg="Loading containers: start."
 time="2025-11-01T16:13:09.282845520Z" level=info msg="Default bridge (docker0) is assigned with an IP address 172.17.0.0/16. Daemon option --bip can be used to set a preferred IP address"
 time="2025-11-01T16:13:09.314458883Z" level=info msg="Loading containers: done."
 time="2025-11-01T16:13:09.327472696Z" level=info msg="Docker daemon" commit=8891c58 graphdriver(s)=overlay2 version=20.10.2
 time="2025-11-01T16:13:09.328021986Z" level=info msg="Daemon has completed initialization"
 time="2025-11-01T16:13:09.358547472Z" level=info msg="API listen on /var/run/docker.sock"
 time="2025-11-01T16:13:09.361432473Z" level=info msg="API listen on [::]:2375"




sudo docker inspect b1223b361a83bf564bda827263b3db3d823ff590ecacc3643b2aae7332259982[
    {
        "Id": "b1223b361a83bf564bda827263b3db3d823ff590ecacc3643b2aae7332259982",
        "Created": "2025-11-01T16:12:52.553753869Z",
        "Path": "dockerd-entrypoint.sh",
        "Args": [
            "-H",
            "tcp://0.0.0.0:2375"
        ],
        "State": {
            "Status": "running",
            "Running": true,
            "Paused": false,
            "Restarting": false,
            "OOMKilled": false,
            "Dead": false,
            "Pid": 43527,
            "ExitCode": 0,
            "Error": "",
            "StartedAt": "2025-11-01T16:12:52.844794656Z",
            "FinishedAt": "0001-01-01T00:00:00Z"
        },
        "Image": "sha256:8f4e9ddda1049e6935f9fc7f5cad0bd1001fbf59188616f19b620fd7b6e95ba2",
        "ResolvConfPath": "/var/lib/docker/containers/b1223b361a83bf564bda827263b3db3d823ff590ecacc3643b2aae7332259982/resolv.conf",
        "HostnamePath": "/var/lib/docker/containers/b1223b361a83bf564bda827263b3db3d823ff590ecacc3643b2aae7332259982/hostname",
        "HostsPath": "/var/lib/docker/containers/b1223b361a83bf564bda827263b3db3d823ff590ecacc3643b2aae7332259982/hosts",
        "LogPath": "/var/lib/docker/containers/b1223b361a83bf564bda827263b3db3d823ff590ecacc3643b2aae7332259982/b1223b361a83bf564bda827263b3db3d823ff590ecacc3643b2aae7332259982-json.log",
        "Name": "/docker_dind",
        "RestartCount": 0,
        "Driver": "overlayfs",
        "Platform": "linux",
        "MountLabel": "",
        "ProcessLabel": "",
        "AppArmorProfile": "",
        "ExecIDs": null,
        "HostConfig": {
            "Binds": null,
            "ContainerIDFile": "",
            "LogConfig": {
                "Type": "json-file",
                "Config": {}
            },
            "NetworkMode": "custom_no_tool_default",
            "PortBindings": {
                "2375/tcp": [
                    {
                        "HostIp": "",
                        "HostPort": "2375"
                    }
                ]
            },
            "RestartPolicy": {
                "Name": "unless-stopped",
                "MaximumRetryCount": 0
            },
            "AutoRemove": false,
            "VolumeDriver": "",
            "VolumesFrom": null,
            "ConsoleSize": [
                0,
                0
            ],
            "CapAdd": null,
            "CapDrop": null,
            "CgroupnsMode": "private",
            "Dns": null,
            "DnsOptions": null,
            "DnsSearch": null,
            "ExtraHosts": [],
            "GroupAdd": null,
            "IpcMode": "private",
            "Cgroup": "",
            "Links": null,
            "OomScoreAdj": 0,
            "PidMode": "",
            "Privileged": true,
            "PublishAllPorts": false,
            "ReadonlyRootfs": false,
            "SecurityOpt": [
                "label=disable"
            ],
            "UTSMode": "",
            "UsernsMode": "",
            "ShmSize": 67108864,
            "Runtime": "runc",
            "Isolation": "",
            "CpuShares": 0,
            "Memory": 0,
            "NanoCpus": 0,
            "CgroupParent": "",
            "BlkioWeight": 0,
            "BlkioWeightDevice": null,
            "BlkioDeviceReadBps": null,
            "BlkioDeviceWriteBps": null,
            "BlkioDeviceReadIOps": null,
            "BlkioDeviceWriteIOps": null,
            "CpuPeriod": 0,
            "CpuQuota": 0,
            "CpuRealtimePeriod": 0,
            "CpuRealtimeRuntime": 0,
            "CpusetCpus": "",
            "CpusetMems": "",
            "Devices": null,
            "DeviceCgroupRules": null,
            "DeviceRequests": null,
            "MemoryReservation": 0,
            "MemorySwap": 0,
            "MemorySwappiness": null,
            "OomKillDisable": null,
            "PidsLimit": null,
            "Ulimits": null,
            "CpuCount": 0,
            "CpuPercent": 0,
            "IOMaximumIOps": 0,
            "IOMaximumBandwidth": 0,
            "MaskedPaths": null,
            "ReadonlyPaths": null
        },
        "GraphDriver": {
            "Data": null,
            "Name": "overlayfs"
        },
        "Mounts": [
            {
                "Type": "volume",
                "Name": "f31dac6db7ebb2bb345fe1e144dd5041f43d68b87b9d068dc03eff6c2341306b",
                "Source": "/var/lib/docker/volumes/f31dac6db7ebb2bb345fe1e144dd5041f43d68b87b9d068dc03eff6c2341306b/_data",
                "Destination": "/var/lib/docker",
                "Driver": "local",
                "Mode": "",
                "RW": true,
                "Propagation": ""
            }
        ],
        "Config": {
            "Hostname": "b1223b361a83",
            "Domainname": "",
            "User": "",
            "AttachStdin": false,
            "AttachStdout": true,
            "AttachStderr": true,
            "ExposedPorts": {
                "2375/tcp": {},
                "2376/tcp": {}
            },
            "Tty": false,
            "OpenStdin": false,
            "StdinOnce": false,
            "Env": [
                "DOCKER_TLS_CERTDIR=",
                "PATH=/usr/local/sbin:/usr/local/bin:/usr/sbin:/usr/bin:/sbin:/bin",
                "DOCKER_VERSION=20.10.2",
                "DIND_COMMIT=ed89041433a031cafc0a0f19cfe573c31688d377"
            ],
            "Cmd": [
                "-H",
                "tcp://0.0.0.0:2375"
            ],
            "Image": "docker:20.10.2-dind",
            "Volumes": {
                "/var/lib/docker": {}
            },
            "WorkingDir": "",
            "Entrypoint": [
                "dockerd-entrypoint.sh"
            ],
            "OnBuild": null,
            "Labels": {
                "com.docker.compose.config-hash": "bda3b73ef82452012d3b73aa4d71ed20e7d14a211130dd4792bb83569b7eb494",
                "com.docker.compose.container-number": "1",
                "com.docker.compose.depends_on": "",
                "com.docker.compose.image": "sha256:8f4e9ddda1049e6935f9fc7f5cad0bd1001fbf59188616f19b620fd7b6e95ba2",
                "com.docker.compose.oneoff": "False",
                "com.docker.compose.project": "custom_no_tool",
                "com.docker.compose.project.config_files": "/home/gabriele/thesis-project/Agents-for-Vulnerable-Dockers-and-related-Benchmarks/dockers/CVE-2021-26120/custom_no_tool/docker-compose.yml",
                "com.docker.compose.project.working_dir": "/home/gabriele/thesis-project/Agents-for-Vulnerable-Dockers-and-related-Benchmarks/dockers/CVE-2021-26120/custom_no_tool",
                "com.docker.compose.service": "docker",
                "com.docker.compose.version": "2.40.2",
                "desktop.docker.io/wsl-distro": "Ubuntu"
            },
            "StopTimeout": 1
        },
        "NetworkSettings": {
            "Bridge": "",
            "SandboxID": "896a0d5caed528f8255cdc3e012938ec7c6cd42a77b5df8edcfb1054da7c1e42",
            "SandboxKey": "/var/run/docker/netns/896a0d5caed5",
            "Ports": {
                "2375/tcp": [
                    {
                        "HostIp": "0.0.0.0",
                        "HostPort": "2375"
                    },
                    {
                        "HostIp": "::",
                        "HostPort": "2375"
                    }
                ]
            },
            "HairpinMode": false,
            "LinkLocalIPv6Address": "",
            "LinkLocalIPv6PrefixLen": 0,
            "SecondaryIPAddresses": null,
            "SecondaryIPv6Addresses": null,
            "EndpointID": "",
            "Gateway": "",
            "GlobalIPv6Address": "",
            "GlobalIPv6PrefixLen": 0,
            "IPAddress": "",
            "IPPrefixLen": 0,
            "IPv6Gateway": "",
            "MacAddress": "",
            "Networks": {
                "custom_no_tool_default": {
                    "IPAMConfig": null,
                    "Links": null,
                    "Aliases": [
                        "docker_dind",
                        "docker"
                    ],
                    "MacAddress": "f6:da:b5:02:c7:71",
                    "DriverOpts": null,
                    "GwPriority": 0,
                    "NetworkID": "336dfbfdf154687a0394b2e7317cd249c809e14608bf358b1b10e01395279a25",
                    "EndpointID": "5b610c4e662caa801a6d80dfc46ec55ed271ce3a0a20778408cdec4b27f96980",
                    "Gateway": "172.18.0.1",
                    "IPAddress": "172.18.0.2",
                    "IPPrefixLen": 16,
                    "IPv6Gateway": "",
                    "GlobalIPv6Address": "",
                    "GlobalIPv6PrefixLen": 0,
                    "DNSNames": [
                        "docker_dind",
                        "docker",
                        "b1223b361a83"
                    ]
                }
            }
        },
        "ImageManifestDescriptor": {
            "mediaType": "application/vnd.docker.distribution.manifest.v2+json",
            "digest": "sha256:12521ff42db0d1e1d99f89c7dea6aa6e2d028c20cb42dad8285503735ddf678d",
            "size": 2614,
            "platform": {
                "architecture": "amd64",
                "os": "linux"
            }
        }
    }
]

sudo docker logs 4dfd3e2c1d9ed41a245516712d0e1ea5ea81d5ae6c7849c14baf21cf2e8fe8ea --details
STDOUT:   * Serving Flask app 'app'
  * Debug mode: off

STDERR:  Traceback (most recent call last):
   File "/usr/local/lib/python3.9/site-packages/urllib3/connection.py", line 198, in _new_conn
     sock = connection.create_connection(
   File "/usr/local/lib/python3.9/site-packages/urllib3/util/connection.py", line 85, in create_connection
     raise err
   File "/usr/local/lib/python3.9/site-packages/urllib3/util/connection.py", line 73, in create_connection
     sock.connect(sa)
 ConnectionRefusedError: [Errno 111] Connection refused
 
 The above exception was the direct cause of the following exception:
 
 Traceback (most recent call last):
   File "/usr/local/lib/python3.9/site-packages/urllib3/connectionpool.py", line 787, in urlopen
     response = self._make_request(
   File "/usr/local/lib/python3.9/site-packages/urllib3/connectionpool.py", line 493, in _make_request
     conn.request(
   File "/usr/local/lib/python3.9/site-packages/urllib3/connection.py", line 494, in request
     self.endheaders()
   File "/usr/local/lib/python3.9/http/client.py", line 1280, in endheaders
     self._send_output(message_body, encode_chunked=encode_chunked)
   File "/usr/local/lib/python3.9/http/client.py", line 1040, in _send_output
     self.send(msg)
   File "/usr/local/lib/python3.9/http/client.py", line 980, in send
     self.connect()
   File "/usr/local/lib/python3.9/site-packages/urllib3/connection.py", line 325, in connect
     self.sock = self._new_conn()
   File "/usr/local/lib/python3.9/site-packages/urllib3/connection.py", line 213, in _new_conn
     raise NewConnectionError(
 urllib3.exceptions.NewConnectionError: <urllib3.connection.HTTPConnection object at 0x70be000a5820>: Failed to establish a new connection: [Errno 111] Connection refused
 
 The above exception was the direct cause of the following exception:
 
 Traceback (most recent call last):
   File "/usr/local/lib/python3.9/site-packages/requests/adapters.py", line 644, in send
     resp = conn.urlopen(
   File "/usr/local/lib/python3.9/site-packages/urllib3/connectionpool.py", line 841, in urlopen
     retries = retries.increment(
   File "/usr/local/lib/python3.9/site-packages/urllib3/util/retry.py", line 519, in increment
     raise MaxRetryError(_pool, url, reason) from reason  # type: ignore[arg-type]
 urllib3.exceptions.MaxRetryError: HTTPConnectionPool(host='docker', port=2375): Max retries exceeded with url: /version (Caused by NewConnectionError('<urllib3.connection.HTTPConnection object at 0x70be000a5820>: Failed to establish a new connection: [Errno 111] Connection refused'))
 
 During handling of the above exception, another exception occurred:
 
 Traceback (most recent call last):
   File "/usr/local/lib/python3.9/site-packages/docker/api/client.py", line 223, in _retrieve_server_version
     return self.version(api_version=False)["ApiVersion"]
   File "/usr/local/lib/python3.9/site-packages/docker/api/daemon.py", line 181, in version
     return self._result(self._get(url), json=True)
   File "/usr/local/lib/python3.9/site-packages/docker/utils/decorators.py", line 44, in inner
     return f(self, *args, **kwargs)
   File "/usr/local/lib/python3.9/site-packages/docker/api/client.py", line 246, in _get
     return self.get(url, **self._set_request_timeout(kwargs))
   File "/usr/local/lib/python3.9/site-packages/requests/sessions.py", line 602, in get
     return self.request("GET", url, **kwargs)
   File "/usr/local/lib/python3.9/site-packages/requests/sessions.py", line 589, in request
     resp = self.send(prep, **send_kwargs)
   File "/usr/local/lib/python3.9/site-packages/requests/sessions.py", line 703, in send
     r = adapter.send(request, **kwargs)
   File "/usr/local/lib/python3.9/site-packages/requests/adapters.py", line 677, in send
     raise ConnectionError(e, request=request)
 requests.exceptions.ConnectionError: HTTPConnectionPool(host='docker', port=2375): Max retries exceeded with url: /version (Caused by NewConnectionError('<urllib3.connection.HTTPConnection object at 0x70be000a5820>: Failed to establish a new connection: [Errno 111] Connection refused'))
 
 The above exception was the direct cause of the following exception:
 
 Traceback (most recent call last):
   File "/app/app.py", line 8, in <module>
     client = docker.DockerClient(base_url='tcp://docker:2375')
   File "/usr/local/lib/python3.9/site-packages/docker/client.py", line 45, in __init__
     self.api = APIClient(*args, **kwargs)
   File "/usr/local/lib/python3.9/site-packages/docker/api/client.py", line 207, in __init__
     self._version = self._retrieve_server_version()
   File "/usr/local/lib/python3.9/site-packages/docker/api/client.py", line 230, in _retrieve_server_version
     raise DockerException(
 docker.errors.DockerException: Error while fetching server API version: HTTPConnectionPool(host='docker', port=2375): Max retries exceeded with url: /version (Caused by NewConnectionError('<urllib3.connection.HTTPConnection object at 0x70be000a5820>: Failed to establish a new connection: [Errno 111] Connection refused'))
 Traceback (most recent call last):
   File "/usr/local/lib/python3.9/site-packages/urllib3/connection.py", line 198, in _new_conn
     sock = connection.create_connection(
   File "/usr/local/lib/python3.9/site-packages/urllib3/util/connection.py", line 85, in create_connection
     raise err
   File "/usr/local/lib/python3.9/site-packages/urllib3/util/connection.py", line 73, in create_connection
     sock.connect(sa)
 ConnectionRefusedError: [Errno 111] Connection refused
 
 The above exception was the direct cause of the following exception:
 
 Traceback (most recent call last):
   File "/usr/local/lib/python3.9/site-packages/urllib3/connectionpool.py", line 787, in urlopen
     response = self._make_request(
   File "/usr/local/lib/python3.9/site-packages/urllib3/connectionpool.py", line 493, in _make_request
     conn.request(
   File "/usr/local/lib/python3.9/site-packages/urllib3/connection.py", line 494, in request
     self.endheaders()
   File "/usr/local/lib/python3.9/http/client.py", line 1280, in endheaders
     self._send_output(message_body, encode_chunked=encode_chunked)
   File "/usr/local/lib/python3.9/http/client.py", line 1040, in _send_output
     self.send(msg)
   File "/usr/local/lib/python3.9/http/client.py", line 980, in send
     self.connect()
   File "/usr/local/lib/python3.9/site-packages/urllib3/connection.py", line 325, in connect
     self.sock = self._new_conn()
   File "/usr/local/lib/python3.9/site-packages/urllib3/connection.py", line 213, in _new_conn
     raise NewConnectionError(
 urllib3.exceptions.NewConnectionError: <urllib3.connection.HTTPConnection object at 0x7f528c50c460>: Failed to establish a new connection: [Errno 111] Connection refused
 
 The above exception was the direct cause of the following exception:
 
 Traceback (most recent call last):
   File "/usr/local/lib/python3.9/site-packages/requests/adapters.py", line 644, in send
     resp = conn.urlopen(
   File "/usr/local/lib/python3.9/site-packages/urllib3/connectionpool.py", line 841, in urlopen
     retries = retries.increment(
   File "/usr/local/lib/python3.9/site-packages/urllib3/util/retry.py", line 519, in increment
     raise MaxRetryError(_pool, url, reason) from reason  # type: ignore[arg-type]
 urllib3.exceptions.MaxRetryError: HTTPConnectionPool(host='docker', port=2375): Max retries exceeded with url: /version (Caused by NewConnectionError('<urllib3.connection.HTTPConnection object at 0x7f528c50c460>: Failed to establish a new connection: [Errno 111] Connection refused'))
 
 During handling of the above exception, another exception occurred:
 
 Traceback (most recent call last):
   File "/usr/local/lib/python3.9/site-packages/docker/api/client.py", line 223, in _retrieve_server_version
     return self.version(api_version=False)["ApiVersion"]
   File "/usr/local/lib/python3.9/site-packages/docker/api/daemon.py", line 181, in version
     return self._result(self._get(url), json=True)
   File "/usr/local/lib/python3.9/site-packages/docker/utils/decorators.py", line 44, in inner
     return f(self, *args, **kwargs)
   File "/usr/local/lib/python3.9/site-packages/docker/api/client.py", line 246, in _get
     return self.get(url, **self._set_request_timeout(kwargs))
   File "/usr/local/lib/python3.9/site-packages/requests/sessions.py", line 602, in get
     return self.request("GET", url, **kwargs)
   File "/usr/local/lib/python3.9/site-packages/requests/sessions.py", line 589, in request
     resp = self.send(prep, **send_kwargs)
   File "/usr/local/lib/python3.9/site-packages/requests/sessions.py", line 703, in send
     r = adapter.send(request, **kwargs)
   File "/usr/local/lib/python3.9/site-packages/requests/adapters.py", line 677, in send
     raise ConnectionError(e, request=request)
 requests.exceptions.ConnectionError: HTTPConnectionPool(host='docker', port=2375): Max retries exceeded with url: /version (Caused by NewConnectionError('<urllib3.connection.HTTPConnection object at 0x7f528c50c460>: Failed to establish a new connection: [Errno 111] Connection refused'))
 
 The above exception was the direct cause of the following exception:
 
 Traceback (most recent call last):
   File "/app/app.py", line 8, in <module>
     client = docker.DockerClient(base_url='tcp://docker:2375')
   File "/usr/local/lib/python3.9/site-packages/docker/client.py", line 45, in __init__
     self.api = APIClient(*args, **kwargs)
   File "/usr/local/lib/python3.9/site-packages/docker/api/client.py", line 207, in __init__
     self._version = self._retrieve_server_version()
   File "/usr/local/lib/python3.9/site-packages/docker/api/client.py", line 230, in _retrieve_server_version
     raise DockerException(
 docker.errors.DockerException: Error while fetching server API version: HTTPConnectionPool(host='docker', port=2375): Max retries exceeded with url: /version (Caused by NewConnectionError('<urllib3.connection.HTTPConnection object at 0x7f528c50c460>: Failed to establish a new connection: [Errno 111] Connection refused'))
 Traceback (most recent call last):
   File "/usr/local/lib/python3.9/site-packages/urllib3/connection.py", line 198, in _new_conn
     sock = connection.create_connection(
   File "/usr/local/lib/python3.9/site-packages/urllib3/util/connection.py", line 85, in create_connection
     raise err
   File "/usr/local/lib/python3.9/site-packages/urllib3/util/connection.py", line 73, in create_connection
     sock.connect(sa)
 ConnectionRefusedError: [Errno 111] Connection refused
 
 The above exception was the direct cause of the following exception:
 
 Traceback (most recent call last):
   File "/usr/local/lib/python3.9/site-packages/urllib3/connectionpool.py", line 787, in urlopen
     response = self._make_request(
   File "/usr/local/lib/python3.9/site-packages/urllib3/connectionpool.py", line 493, in _make_request
     conn.request(
   File "/usr/local/lib/python3.9/site-packages/urllib3/connection.py", line 494, in request
     self.endheaders()
   File "/usr/local/lib/python3.9/http/client.py", line 1280, in endheaders
     self._send_output(message_body, encode_chunked=encode_chunked)
   File "/usr/local/lib/python3.9/http/client.py", line 1040, in _send_output
     self.send(msg)
   File "/usr/local/lib/python3.9/http/client.py", line 980, in send
     self.connect()
   File "/usr/local/lib/python3.9/site-packages/urllib3/connection.py", line 325, in connect
     self.sock = self._new_conn()
   File "/usr/local/lib/python3.9/site-packages/urllib3/connection.py", line 213, in _new_conn
     raise NewConnectionError(
 urllib3.exceptions.NewConnectionError: <urllib3.connection.HTTPConnection object at 0x703ea95ae460>: Failed to establish a new connection: [Errno 111] Connection refused
 
 The above exception was the direct cause of the following exception:
 
 Traceback (most recent call last):
   File "/usr/local/lib/python3.9/site-packages/requests/adapters.py", line 644, in send
     resp = conn.urlopen(
   File "/usr/local/lib/python3.9/site-packages/urllib3/connectionpool.py", line 841, in urlopen
     retries = retries.increment(
   File "/usr/local/lib/python3.9/site-packages/urllib3/util/retry.py", line 519, in increment
     raise MaxRetryError(_pool, url, reason) from reason  # type: ignore[arg-type]
 urllib3.exceptions.MaxRetryError: HTTPConnectionPool(host='docker', port=2375): Max retries exceeded with url: /version (Caused by NewConnectionError('<urllib3.connection.HTTPConnection object at 0x703ea95ae460>: Failed to establish a new connection: [Errno 111] Connection refused'))
 
 During handling of the above exception, another exception occurred:
 
 Traceback (most recent call last):
   File "/usr/local/lib/python3.9/site-packages/docker/api/client.py", line 223, in _retrieve_server_version
     return self.version(api_version=False)["ApiVersion"]
   File "/usr/local/lib/python3.9/site-packages/docker/api/daemon.py", line 181, in version
     return self._result(self._get(url), json=True)
   File "/usr/local/lib/python3.9/site-packages/docker/utils/decorators.py", line 44, in inner
     return f(self, *args, **kwargs)
   File "/usr/local/lib/python3.9/site-packages/docker/api/client.py", line 246, in _get
     return self.get(url, **self._set_request_timeout(kwargs))
   File "/usr/local/lib/python3.9/site-packages/requests/sessions.py", line 602, in get
     return self.request("GET", url, **kwargs)
   File "/usr/local/lib/python3.9/site-packages/requests/sessions.py", line 589, in request
     resp = self.send(prep, **send_kwargs)
   File "/usr/local/lib/python3.9/site-packages/requests/sessions.py", line 703, in send
     r = adapter.send(request, **kwargs)
   File "/usr/local/lib/python3.9/site-packages/requests/adapters.py", line 677, in send
     raise ConnectionError(e, request=request)
 requests.exceptions.ConnectionError: HTTPConnectionPool(host='docker', port=2375): Max retries exceeded with url: /version (Caused by NewConnectionError('<urllib3.connection.HTTPConnection object at 0x703ea95ae460>: Failed to establish a new connection: [Errno 111] Connection refused'))
 
 The above exception was the direct cause of the following exception:
 
 Traceback (most recent call last):
   File "/app/app.py", line 8, in <module>
     client = docker.DockerClient(base_url='tcp://docker:2375')
   File "/usr/local/lib/python3.9/site-packages/docker/client.py", line 45, in __init__
     self.api = APIClient(*args, **kwargs)
   File "/usr/local/lib/python3.9/site-packages/docker/api/client.py", line 207, in __init__
     self._version = self._retrieve_server_version()
   File "/usr/local/lib/python3.9/site-packages/docker/api/client.py", line 230, in _retrieve_server_version
     raise DockerException(
 docker.errors.DockerException: Error while fetching server API version: HTTPConnectionPool(host='docker', port=2375): Max retries exceeded with url: /version (Caused by NewConnectionError('<urllib3.connection.HTTPConnection object at 0x703ea95ae460>: Failed to establish a new connection: [Errno 111] Connection refused'))
 Traceback (most recent call last):
   File "/usr/local/lib/python3.9/site-packages/urllib3/connection.py", line 198, in _new_conn
     sock = connection.create_connection(
   File "/usr/local/lib/python3.9/site-packages/urllib3/util/connection.py", line 85, in create_connection
     raise err
   File "/usr/local/lib/python3.9/site-packages/urllib3/util/connection.py", line 73, in create_connection
     sock.connect(sa)
 ConnectionRefusedError: [Errno 111] Connection refused
 
 The above exception was the direct cause of the following exception:
 
 Traceback (most recent call last):
   File "/usr/local/lib/python3.9/site-packages/urllib3/connectionpool.py", line 787, in urlopen
     response = self._make_request(
   File "/usr/local/lib/python3.9/site-packages/urllib3/connectionpool.py", line 493, in _make_request
     conn.request(
   File "/usr/local/lib/python3.9/site-packages/urllib3/connection.py", line 494, in request
     self.endheaders()
   File "/usr/local/lib/python3.9/http/client.py", line 1280, in endheaders
     self._send_output(message_body, encode_chunked=encode_chunked)
   File "/usr/local/lib/python3.9/http/client.py", line 1040, in _send_output
     self.send(msg)
   File "/usr/local/lib/python3.9/http/client.py", line 980, in send
     self.connect()
   File "/usr/local/lib/python3.9/site-packages/urllib3/connection.py", line 325, in connect
     self.sock = self._new_conn()
   File "/usr/local/lib/python3.9/site-packages/urllib3/connection.py", line 213, in _new_conn
     raise NewConnectionError(
 urllib3.exceptions.NewConnectionError: <urllib3.connection.HTTPConnection object at 0x7c2aff3f8460>: Failed to establish a new connection: [Errno 111] Connection refused
 
 The above exception was the direct cause of the following exception:
 
 Traceback (most recent call last):
   File "/usr/local/lib/python3.9/site-packages/requests/adapters.py", line 644, in send
     resp = conn.urlopen(
   File "/usr/local/lib/python3.9/site-packages/urllib3/connectionpool.py", line 841, in urlopen
     retries = retries.increment(
   File "/usr/local/lib/python3.9/site-packages/urllib3/util/retry.py", line 519, in increment
     raise MaxRetryError(_pool, url, reason) from reason  # type: ignore[arg-type]
 urllib3.exceptions.MaxRetryError: HTTPConnectionPool(host='docker', port=2375): Max retries exceeded with url: /version (Caused by NewConnectionError('<urllib3.connection.HTTPConnection object at 0x7c2aff3f8460>: Failed to establish a new connection: [Errno 111] Connection refused'))
 
 During handling of the above exception, another exception occurred:
 
 Traceback (most recent call last):
   File "/usr/local/lib/python3.9/site-packages/docker/api/client.py", line 223, in _retrieve_server_version
     return self.version(api_version=False)["ApiVersion"]
   File "/usr/local/lib/python3.9/site-packages/docker/api/daemon.py", line 181, in version
     return self._result(self._get(url), json=True)
   File "/usr/local/lib/python3.9/site-packages/docker/utils/decorators.py", line 44, in inner
     return f(self, *args, **kwargs)
   File "/usr/local/lib/python3.9/site-packages/docker/api/client.py", line 246, in _get
     return self.get(url, **self._set_request_timeout(kwargs))
   File "/usr/local/lib/python3.9/site-packages/requests/sessions.py", line 602, in get
     return self.request("GET", url, **kwargs)
   File "/usr/local/lib/python3.9/site-packages/requests/sessions.py", line 589, in request
     resp = self.send(prep, **send_kwargs)
   File "/usr/local/lib/python3.9/site-packages/requests/sessions.py", line 703, in send
     r = adapter.send(request, **kwargs)
   File "/usr/local/lib/python3.9/site-packages/requests/adapters.py", line 677, in send
     raise ConnectionError(e, request=request)
 requests.exceptions.ConnectionError: HTTPConnectionPool(host='docker', port=2375): Max retries exceeded with url: /version (Caused by NewConnectionError('<urllib3.connection.HTTPConnection object at 0x7c2aff3f8460>: Failed to establish a new connection: [Errno 111] Connection refused'))
 
 The above exception was the direct cause of the following exception:
 
 Traceback (most recent call last):
   File "/app/app.py", line 8, in <module>
     client = docker.DockerClient(base_url='tcp://docker:2375')
   File "/usr/local/lib/python3.9/site-packages/docker/client.py", line 45, in __init__
     self.api = APIClient(*args, **kwargs)
   File "/usr/local/lib/python3.9/site-packages/docker/api/client.py", line 207, in __init__
     self._version = self._retrieve_server_version()
   File "/usr/local/lib/python3.9/site-packages/docker/api/client.py", line 230, in _retrieve_server_version
     raise DockerException(
 docker.errors.DockerException: Error while fetching server API version: HTTPConnectionPool(host='docker', port=2375): Max retries exceeded with url: /version (Caused by NewConnectionError('<urllib3.connection.HTTPConnection object at 0x7c2aff3f8460>: Failed to establish a new connection: [Errno 111] Connection refused'))
 Traceback (most recent call last):
   File "/usr/local/lib/python3.9/site-packages/urllib3/connection.py", line 198, in _new_conn
     sock = connection.create_connection(
   File "/usr/local/lib/python3.9/site-packages/urllib3/util/connection.py", line 85, in create_connection
     raise err
   File "/usr/local/lib/python3.9/site-packages/urllib3/util/connection.py", line 73, in create_connection
     sock.connect(sa)
 ConnectionRefusedError: [Errno 111] Connection refused
 
 The above exception was the direct cause of the following exception:
 
 Traceback (most recent call last):
   File "/usr/local/lib/python3.9/site-packages/urllib3/connectionpool.py", line 787, in urlopen
     response = self._make_request(
   File "/usr/local/lib/python3.9/site-packages/urllib3/connectionpool.py", line 493, in _make_request
     conn.request(
   File "/usr/local/lib/python3.9/site-packages/urllib3/connection.py", line 494, in request
     self.endheaders()
   File "/usr/local/lib/python3.9/http/client.py", line 1280, in endheaders
     self._send_output(message_body, encode_chunked=encode_chunked)
   File "/usr/local/lib/python3.9/http/client.py", line 1040, in _send_output
     self.send(msg)
   File "/usr/local/lib/python3.9/http/client.py", line 980, in send
     self.connect()
   File "/usr/local/lib/python3.9/site-packages/urllib3/connection.py", line 325, in connect
     self.sock = self._new_conn()
   File "/usr/local/lib/python3.9/site-packages/urllib3/connection.py", line 213, in _new_conn
     raise NewConnectionError(
 urllib3.exceptions.NewConnectionError: <urllib3.connection.HTTPConnection object at 0x71d3b72f9460>: Failed to establish a new connection: [Errno 111] Connection refused
 
 The above exception was the direct cause of the following exception:
 
 Traceback (most recent call last):
   File "/usr/local/lib/python3.9/site-packages/requests/adapters.py", line 644, in send
     resp = conn.urlopen(
   File "/usr/local/lib/python3.9/site-packages/urllib3/connectionpool.py", line 841, in urlopen
     retries = retries.increment(
   File "/usr/local/lib/python3.9/site-packages/urllib3/util/retry.py", line 519, in increment
     raise MaxRetryError(_pool, url, reason) from reason  # type: ignore[arg-type]
 urllib3.exceptions.MaxRetryError: HTTPConnectionPool(host='docker', port=2375): Max retries exceeded with url: /version (Caused by NewConnectionError('<urllib3.connection.HTTPConnection object at 0x71d3b72f9460>: Failed to establish a new connection: [Errno 111] Connection refused'))
 
 During handling of the above exception, another exception occurred:
 
 Traceback (most recent call last):
   File "/usr/local/lib/python3.9/site-packages/docker/api/client.py", line 223, in _retrieve_server_version
     return self.version(api_version=False)["ApiVersion"]
   File "/usr/local/lib/python3.9/site-packages/docker/api/daemon.py", line 181, in version
     return self._result(self._get(url), json=True)
   File "/usr/local/lib/python3.9/site-packages/docker/utils/decorators.py", line 44, in inner
     return f(self, *args, **kwargs)
   File "/usr/local/lib/python3.9/site-packages/docker/api/client.py", line 246, in _get
     return self.get(url, **self._set_request_timeout(kwargs))
   File "/usr/local/lib/python3.9/site-packages/requests/sessions.py", line 602, in get
     return self.request("GET", url, **kwargs)
   File "/usr/local/lib/python3.9/site-packages/requests/sessions.py", line 589, in request
     resp = self.send(prep, **send_kwargs)
   File "/usr/local/lib/python3.9/site-packages/requests/sessions.py", line 703, in send
     r = adapter.send(request, **kwargs)
   File "/usr/local/lib/python3.9/site-packages/requests/adapters.py", line 677, in send
     raise ConnectionError(e, request=request)
 requests.exceptions.ConnectionError: HTTPConnectionPool(host='docker', port=2375): Max retries exceeded with url: /version (Caused by NewConnectionError('<urllib3.connection.HTTPConnection object at 0x71d3b72f9460>: Failed to establish a new connection: [Errno 111] Connection refused'))
 
 The above exception was the direct cause of the following exception:
 
 Traceback (most recent call last):
   File "/app/app.py", line 8, in <module>
     client = docker.DockerClient(base_url='tcp://docker:2375')
   File "/usr/local/lib/python3.9/site-packages/docker/client.py", line 45, in __init__
     self.api = APIClient(*args, **kwargs)
   File "/usr/local/lib/python3.9/site-packages/docker/api/client.py", line 207, in __init__
     self._version = self._retrieve_server_version()
   File "/usr/local/lib/python3.9/site-packages/docker/api/client.py", line 230, in _retrieve_server_version
     raise DockerException(
 docker.errors.DockerException: Error while fetching server API version: HTTPConnectionPool(host='docker', port=2375): Max retries exceeded with url: /version (Caused by NewConnectionError('<urllib3.connection.HTTPConnection object at 0x71d3b72f9460>: Failed to establish a new connection: [Errno 111] Connection refused'))
 Traceback (most recent call last):
   File "/usr/local/lib/python3.9/site-packages/urllib3/connection.py", line 198, in _new_conn
     sock = connection.create_connection(
   File "/usr/local/lib/python3.9/site-packages/urllib3/util/connection.py", line 85, in create_connection
     raise err
   File "/usr/local/lib/python3.9/site-packages/urllib3/util/connection.py", line 73, in create_connection
     sock.connect(sa)
 ConnectionRefusedError: [Errno 111] Connection refused
 
 The above exception was the direct cause of the following exception:
 
 Traceback (most recent call last):
   File "/usr/local/lib/python3.9/site-packages/urllib3/connectionpool.py", line 787, in urlopen
     response = self._make_request(
   File "/usr/local/lib/python3.9/site-packages/urllib3/connectionpool.py", line 493, in _make_request
     conn.request(
   File "/usr/local/lib/python3.9/site-packages/urllib3/connection.py", line 494, in request
     self.endheaders()
   File "/usr/local/lib/python3.9/http/client.py", line 1280, in endheaders
     self._send_output(message_body, encode_chunked=encode_chunked)
   File "/usr/local/lib/python3.9/http/client.py", line 1040, in _send_output
     self.send(msg)
   File "/usr/local/lib/python3.9/http/client.py", line 980, in send
     self.connect()
   File "/usr/local/lib/python3.9/site-packages/urllib3/connection.py", line 325, in connect
     self.sock = self._new_conn()
   File "/usr/local/lib/python3.9/site-packages/urllib3/connection.py", line 213, in _new_conn
     raise NewConnectionError(
 urllib3.exceptions.NewConnectionError: <urllib3.connection.HTTPConnection object at 0x710d1cb55460>: Failed to establish a new connection: [Errno 111] Connection refused
 
 The above exception was the direct cause of the following exception:
 
 Traceback (most recent call last):
   File "/usr/local/lib/python3.9/site-packages/requests/adapters.py", line 644, in send
     resp = conn.urlopen(
   File "/usr/local/lib/python3.9/site-packages/urllib3/connectionpool.py", line 841, in urlopen
     retries = retries.increment(
   File "/usr/local/lib/python3.9/site-packages/urllib3/util/retry.py", line 519, in increment
     raise MaxRetryError(_pool, url, reason) from reason  # type: ignore[arg-type]
 urllib3.exceptions.MaxRetryError: HTTPConnectionPool(host='docker', port=2375): Max retries exceeded with url: /version (Caused by NewConnectionError('<urllib3.connection.HTTPConnection object at 0x710d1cb55460>: Failed to establish a new connection: [Errno 111] Connection refused'))
 
 During handling of the above exception, another exception occurred:
 
 Traceback (most recent call last):
   File "/usr/local/lib/python3.9/site-packages/docker/api/client.py", line 223, in _retrieve_server_version
     return self.version(api_version=False)["ApiVersion"]
   File "/usr/local/lib/python3.9/site-packages/docker/api/daemon.py", line 181, in version
     return self._result(self._get(url), json=True)
   File "/usr/local/lib/python3.9/site-packages/docker/utils/decorators.py", line 44, in inner
     return f(self, *args, **kwargs)
   File "/usr/local/lib/python3.9/site-packages/docker/api/client.py", line 246, in _get
     return self.get(url, **self._set_request_timeout(kwargs))
   File "/usr/local/lib/python3.9/site-packages/requests/sessions.py", line 602, in get
     return self.request("GET", url, **kwargs)
   File "/usr/local/lib/python3.9/site-packages/requests/sessions.py", line 589, in request
     resp = self.send(prep, **send_kwargs)
   File "/usr/local/lib/python3.9/site-packages/requests/sessions.py", line 703, in send
     r = adapter.send(request, **kwargs)
   File "/usr/local/lib/python3.9/site-packages/requests/adapters.py", line 677, in send
     raise ConnectionError(e, request=request)
 requests.exceptions.ConnectionError: HTTPConnectionPool(host='docker', port=2375): Max retries exceeded with url: /version (Caused by NewConnectionError('<urllib3.connection.HTTPConnection object at 0x710d1cb55460>: Failed to establish a new connection: [Errno 111] Connection refused'))
 
 The above exception was the direct cause of the following exception:
 
 Traceback (most recent call last):
   File "/app/app.py", line 8, in <module>
     client = docker.DockerClient(base_url='tcp://docker:2375')
   File "/usr/local/lib/python3.9/site-packages/docker/client.py", line 45, in __init__
     self.api = APIClient(*args, **kwargs)
   File "/usr/local/lib/python3.9/site-packages/docker/api/client.py", line 207, in __init__
     self._version = self._retrieve_server_version()
   File "/usr/local/lib/python3.9/site-packages/docker/api/client.py", line 230, in _retrieve_server_version
     raise DockerException(
 docker.errors.DockerException: Error while fetching server API version: HTTPConnectionPool(host='docker', port=2375): Max retries exceeded with url: /version (Caused by NewConnectionError('<urllib3.connection.HTTPConnection object at 0x710d1cb55460>: Failed to establish a new connection: [Errno 111] Connection refused'))
 Traceback (most recent call last):
   File "/usr/local/lib/python3.9/site-packages/urllib3/connection.py", line 198, in _new_conn
     sock = connection.create_connection(
   File "/usr/local/lib/python3.9/site-packages/urllib3/util/connection.py", line 85, in create_connection
     raise err
   File "/usr/local/lib/python3.9/site-packages/urllib3/util/connection.py", line 73, in create_connection
     sock.connect(sa)
 ConnectionRefusedError: [Errno 111] Connection refused
 
 The above exception was the direct cause of the following exception:
 
 Traceback (most recent call last):
   File "/usr/local/lib/python3.9/site-packages/urllib3/connectionpool.py", line 787, in urlopen
     response = self._make_request(
   File "/usr/local/lib/python3.9/site-packages/urllib3/connectionpool.py", line 493, in _make_request
     conn.request(
   File "/usr/local/lib/python3.9/site-packages/urllib3/connection.py", line 494, in request
     self.endheaders()
   File "/usr/local/lib/python3.9/http/client.py", line 1280, in endheaders
     self._send_output(message_body, encode_chunked=encode_chunked)
   File "/usr/local/lib/python3.9/http/client.py", line 1040, in _send_output
     self.send(msg)
   File "/usr/local/lib/python3.9/http/client.py", line 980, in send
     self.connect()
   File "/usr/local/lib/python3.9/site-packages/urllib3/connection.py", line 325, in connect
     self.sock = self._new_conn()
   File "/usr/local/lib/python3.9/site-packages/urllib3/connection.py", line 213, in _new_conn
     raise NewConnectionError(
 urllib3.exceptions.NewConnectionError: <urllib3.connection.HTTPConnection object at 0x7ea1cd32e460>: Failed to establish a new connection: [Errno 111] Connection refused
 
 The above exception was the direct cause of the following exception:
 
 Traceback (most recent call last):
   File "/usr/local/lib/python3.9/site-packages/requests/adapters.py", line 644, in send
     resp = conn.urlopen(
   File "/usr/local/lib/python3.9/site-packages/urllib3/connectionpool.py", line 841, in urlopen
     retries = retries.increment(
   File "/usr/local/lib/python3.9/site-packages/urllib3/util/retry.py", line 519, in increment
     raise MaxRetryError(_pool, url, reason) from reason  # type: ignore[arg-type]
 urllib3.exceptions.MaxRetryError: HTTPConnectionPool(host='docker', port=2375): Max retries exceeded with url: /version (Caused by NewConnectionError('<urllib3.connection.HTTPConnection object at 0x7ea1cd32e460>: Failed to establish a new connection: [Errno 111] Connection refused'))
 
 During handling of the above exception, another exception occurred:
 
 Traceback (most recent call last):
   File "/usr/local/lib/python3.9/site-packages/docker/api/client.py", line 223, in _retrieve_server_version
     return self.version(api_version=False)["ApiVersion"]
   File "/usr/local/lib/python3.9/site-packages/docker/api/daemon.py", line 181, in version
     return self._result(self._get(url), json=True)
   File "/usr/local/lib/python3.9/site-packages/docker/utils/decorators.py", line 44, in inner
     return f(self, *args, **kwargs)
   File "/usr/local/lib/python3.9/site-packages/docker/api/client.py", line 246, in _get
     return self.get(url, **self._set_request_timeout(kwargs))
   File "/usr/local/lib/python3.9/site-packages/requests/sessions.py", line 602, in get
     return self.request("GET", url, **kwargs)
   File "/usr/local/lib/python3.9/site-packages/requests/sessions.py", line 589, in request
     resp = self.send(prep, **send_kwargs)
   File "/usr/local/lib/python3.9/site-packages/requests/sessions.py", line 703, in send
     r = adapter.send(request, **kwargs)
   File "/usr/local/lib/python3.9/site-packages/requests/adapters.py", line 677, in send
     raise ConnectionError(e, request=request)
 requests.exceptions.ConnectionError: HTTPConnectionPool(host='docker', port=2375): Max retries exceeded with url: /version (Caused by NewConnectionError('<urllib3.connection.HTTPConnection object at 0x7ea1cd32e460>: Failed to establish a new connection: [Errno 111] Connection refused'))
 
 The above exception was the direct cause of the following exception:
 
 Traceback (most recent call last):
   File "/app/app.py", line 8, in <module>
     client = docker.DockerClient(base_url='tcp://docker:2375')
   File "/usr/local/lib/python3.9/site-packages/docker/client.py", line 45, in __init__
     self.api = APIClient(*args, **kwargs)
   File "/usr/local/lib/python3.9/site-packages/docker/api/client.py", line 207, in __init__
     self._version = self._retrieve_server_version()
   File "/usr/local/lib/python3.9/site-packages/docker/api/client.py", line 230, in _retrieve_server_version
     raise DockerException(
 docker.errors.DockerException: Error while fetching server API version: HTTPConnectionPool(host='docker', port=2375): Max retries exceeded with url: /version (Caused by NewConnectionError('<urllib3.connection.HTTPConnection object at 0x7ea1cd32e460>: Failed to establish a new connection: [Errno 111] Connection refused'))
 [31m[1mWARNING: This is a development server. Do not use it in a production deployment. Use a production WSGI server instead.[0m
  * Running on all addresses (0.0.0.0)
  * Running on http://127.0.0.1:5000
  * Running on http://172.18.0.4:5000
 [33mPress CTRL+C to quit[0m




sudo docker inspect 4dfd3e2c1d9ed41a245516712d0e1ea5ea81d5ae6c7849c14baf21cf2e8fe8ea[
    {
        "Id": "4dfd3e2c1d9ed41a245516712d0e1ea5ea81d5ae6c7849c14baf21cf2e8fe8ea",
        "Created": "2025-11-01T16:12:52.669717672Z",
        "Path": "python",
        "Args": [
            "app.py"
        ],
        "State": {
            "Status": "running",
            "Running": true,
            "Paused": false,
            "Restarting": false,
            "OOMKilled": false,
            "Dead": false,
            "Pid": 44594,
            "ExitCode": 0,
            "Error": "",
            "StartedAt": "2025-11-01T16:13:09.723155312Z",
            "FinishedAt": "2025-11-01T16:13:03.558115096Z"
        },
        "Image": "sha256:617f37ed0e05ab55de1a2fdd5ca27e23fc5513d83673e3cdc0fbe2e004ce829a",
        "ResolvConfPath": "/var/lib/docker/containers/4dfd3e2c1d9ed41a245516712d0e1ea5ea81d5ae6c7849c14baf21cf2e8fe8ea/resolv.conf",
        "HostnamePath": "/var/lib/docker/containers/4dfd3e2c1d9ed41a245516712d0e1ea5ea81d5ae6c7849c14baf21cf2e8fe8ea/hostname",
        "HostsPath": "/var/lib/docker/containers/4dfd3e2c1d9ed41a245516712d0e1ea5ea81d5ae6c7849c14baf21cf2e8fe8ea/hosts",
        "LogPath": "/var/lib/docker/containers/4dfd3e2c1d9ed41a245516712d0e1ea5ea81d5ae6c7849c14baf21cf2e8fe8ea/4dfd3e2c1d9ed41a245516712d0e1ea5ea81d5ae6c7849c14baf21cf2e8fe8ea-json.log",
        "Name": "/vulnerable_app",
        "RestartCount": 7,
        "Driver": "overlayfs",
        "Platform": "linux",
        "MountLabel": "",
        "ProcessLabel": "",
        "AppArmorProfile": "",
        "ExecIDs": null,
        "HostConfig": {
            "Binds": null,
            "ContainerIDFile": "",
            "LogConfig": {
                "Type": "json-file",
                "Config": {}
            },
            "NetworkMode": "custom_no_tool_default",
            "PortBindings": {
                "5000/tcp": [
                    {
                        "HostIp": "",
                        "HostPort": "5000"
                    }
                ]
            },
            "RestartPolicy": {
                "Name": "unless-stopped",
                "MaximumRetryCount": 0
            },
            "AutoRemove": false,
            "VolumeDriver": "",
            "VolumesFrom": null,
            "ConsoleSize": [
                0,
                0
            ],
            "CapAdd": null,
            "CapDrop": null,
            "CgroupnsMode": "private",
            "Dns": null,
            "DnsOptions": null,
            "DnsSearch": null,
            "ExtraHosts": [],
            "GroupAdd": null,
            "IpcMode": "private",
            "Cgroup": "",
            "Links": null,
            "OomScoreAdj": 0,
            "PidMode": "",
            "Privileged": false,
            "PublishAllPorts": false,
            "ReadonlyRootfs": false,
            "SecurityOpt": null,
            "UTSMode": "",
            "UsernsMode": "",
            "ShmSize": 67108864,
            "Runtime": "runc",
            "Isolation": "",
            "CpuShares": 0,
            "Memory": 0,
            "NanoCpus": 0,
            "CgroupParent": "",
            "BlkioWeight": 0,
            "BlkioWeightDevice": null,
            "BlkioDeviceReadBps": null,
            "BlkioDeviceWriteBps": null,
            "BlkioDeviceReadIOps": null,
            "BlkioDeviceWriteIOps": null,
            "CpuPeriod": 0,
            "CpuQuota": 0,
            "CpuRealtimePeriod": 0,
            "CpuRealtimeRuntime": 0,
            "CpusetCpus": "",
            "CpusetMems": "",
            "Devices": null,
            "DeviceCgroupRules": null,
            "DeviceRequests": null,
            "MemoryReservation": 0,
            "MemorySwap": 0,
            "MemorySwappiness": null,
            "OomKillDisable": null,
            "PidsLimit": null,
            "Ulimits": null,
            "CpuCount": 0,
            "CpuPercent": 0,
            "IOMaximumIOps": 0,
            "IOMaximumBandwidth": 0,
            "MaskedPaths": [
                "/proc/asound",
                "/proc/acpi",
                "/proc/interrupts",
                "/proc/kcore",
                "/proc/keys",
                "/proc/latency_stats",
                "/proc/timer_list",
                "/proc/timer_stats",
                "/proc/sched_debug",
                "/proc/scsi",
                "/sys/firmware",
                "/sys/devices/virtual/powercap"
            ],
            "ReadonlyPaths": [
                "/proc/bus",
                "/proc/fs",
                "/proc/irq",
                "/proc/sys",
                "/proc/sysrq-trigger"
            ]
        },
        "GraphDriver": {
            "Data": null,
            "Name": "overlayfs"
        },
        "Mounts": [],
        "Config": {
            "Hostname": "4dfd3e2c1d9e",
            "Domainname": "",
            "User": "",
            "AttachStdin": false,
            "AttachStdout": true,
            "AttachStderr": true,
            "ExposedPorts": {
                "5000/tcp": {}
            },
            "Tty": false,
            "OpenStdin": false,
            "StdinOnce": false,
            "Env": [
                "DOCKER_HOST=tcp://docker:2375",
                "PATH=/usr/local/bin:/usr/local/sbin:/usr/local/bin:/usr/sbin:/usr/bin:/sbin:/bin",
                "LANG=C.UTF-8",
                "GPG_KEY=E3FF2839C048B25C084DEBE9B26995E310250568",
                "PYTHON_VERSION=3.9.25",
                "PYTHON_SHA256=00e07d7c0f2f0cc002432d1ee84d2a40dae404a99303e3f97701c10966c91834"
            ],
            "Cmd": [
                "python",
                "app.py"
            ],
            "Image": "vulnerable_app:latest",
            "Volumes": null,
            "WorkingDir": "/app",
            "Entrypoint": null,
            "OnBuild": null,
            "Labels": {
                "com.docker.compose.config-hash": "49a483f7444948fb97c287654f3ab21b417396ba858b39211140593c45206a9f",
                "com.docker.compose.container-number": "1",
                "com.docker.compose.depends_on": "docker:service_started:false",
                "com.docker.compose.image": "sha256:617f37ed0e05ab55de1a2fdd5ca27e23fc5513d83673e3cdc0fbe2e004ce829a",
                "com.docker.compose.oneoff": "False",
                "com.docker.compose.project": "custom_no_tool",
                "com.docker.compose.project.config_files": "/home/gabriele/thesis-project/Agents-for-Vulnerable-Dockers-and-related-Benchmarks/dockers/CVE-2021-26120/custom_no_tool/docker-compose.yml",
                "com.docker.compose.project.working_dir": "/home/gabriele/thesis-project/Agents-for-Vulnerable-Dockers-and-related-Benchmarks/dockers/CVE-2021-26120/custom_no_tool",
                "com.docker.compose.service": "vulnerable_app",
                "com.docker.compose.version": "2.40.2",
                "desktop.docker.io/wsl-distro": "Ubuntu"
            },
            "StopTimeout": 1
        },
        "NetworkSettings": {
            "Bridge": "",
            "SandboxID": "d2a5a6af95d927dbb7e093bffa29ed5da477ccf52dccad9bfb8d0333ec2c8950",
            "SandboxKey": "/var/run/docker/netns/d2a5a6af95d9",
            "Ports": {
                "5000/tcp": [
                    {
                        "HostIp": "0.0.0.0",
                        "HostPort": "5000"
                    },
                    {
                        "HostIp": "::",
                        "HostPort": "5000"
                    }
                ]
            },
            "HairpinMode": false,
            "LinkLocalIPv6Address": "",
            "LinkLocalIPv6PrefixLen": 0,
            "SecondaryIPAddresses": null,
            "SecondaryIPv6Addresses": null,
            "EndpointID": "",
            "Gateway": "",
            "GlobalIPv6Address": "",
            "GlobalIPv6PrefixLen": 0,
            "IPAddress": "",
            "IPPrefixLen": 0,
            "IPv6Gateway": "",
            "MacAddress": "",
            "Networks": {
                "custom_no_tool_default": {
                    "IPAMConfig": null,
                    "Links": null,
                    "Aliases": [
                        "vulnerable_app",
                        "vulnerable_app"
                    ],
                    "MacAddress": "c2:c8:3e:f6:d6:25",
                    "DriverOpts": null,
                    "GwPriority": 0,
                    "NetworkID": "336dfbfdf154687a0394b2e7317cd249c809e14608bf358b1b10e01395279a25",
                    "EndpointID": "d9d0af83fc0af4ebb5715912c0662df88fc81f50105be8b6cc4d243d4c96d9ba",
                    "Gateway": "172.18.0.1",
                    "IPAddress": "172.18.0.4",
                    "IPPrefixLen": 16,
                    "IPv6Gateway": "",
                    "GlobalIPv6Address": "",
                    "GlobalIPv6PrefixLen": 0,
                    "DNSNames": [
                        "vulnerable_app",
                        "4dfd3e2c1d9e"
                    ]
                }
            }
        },
        "ImageManifestDescriptor": {
            "mediaType": "application/vnd.oci.image.manifest.v1+json",
            "digest": "sha256:93b5c63cfa1ef26f39aef6d3787edbf26ab7da9502a70b7424ef2d7847156f40",
            "size": 1622,
            "platform": {
                "architecture": "amd64",
                "os": "linux"
            }
        }
    }
]